@CodeReview(approved = true)

Мы получим:
1. Got the Test Exception
   Inside finally block