Дано

class TestException extends Exception { }

class Main {
   public static void main(String args[]) {
      try {
         throw new TestException();
      } catch(TestException t) {
         System.out.println("Got the Test Exception");
      } finally {
         System.out.println("Inside finally block ");
      }
  }
}

@CodeReview(approved = true)

Какой результат мы получим?
1. Got the Test Exception   +++  Будет поймана TestException ошибка в try и сработает catch i finally
   Inside finally block

2. Got the Test Exception

3. Inside finally block

4. Compiler Error
